<!--
 ~ Copyright Vikash Kumar
 ~
 ~ Licensed under the Apache License, Version 2.0 (the "License");
 ~ you may not use this file except in compliance with the License.
 ~ You may obtain a copy of the License at
 ~
 ~     http://www.apache.org/licenses/LICENSE-2.0
 ~
 ~ Unless required by applicable law or agreed to in writing, software
 ~ distributed under the License is distributed on an "AS IS" BASIS,
 ~ WITHOUT WARRANTIES OR CONDITIONS OF ANY KIND, either express or implied.
 ~ See the License for the specific language governing permissions and
 ~ limitations under the License.
 -->

<!-- ======================================================
    Extracted and Modified by Sudeep Dasari
====================================================== -->


<mujoco model='dmanus'>

    <compiler angle="radian" meshdir="."/>
    <asset>
        <mesh name="X430" file="../../meshes/dmanus_sim/meshes/highres/X430.stl" scale="1 1 1"/>
        <mesh name="FR121" file="../../meshes/dmanus_sim/meshes/highres/FR121.stl" scale="1 1 1"/>
        <mesh name="FR123" file="../../meshes/dmanus_sim/meshes/highres/FR123.stl" scale="1 1 1"/>
        <mesh name="skeleton" file="../../meshes/dmanus_sim/meshes/highres/skeleton.stl" scale="1 1 1"/>
        <mesh name="fingertip" file="../../meshes/dmanus_sim/meshes/highres/fingertip.stl" scale="1 1 1"/>
        <mesh name="plate" file="../../meshes/dmanus_sim/meshes/highres/plate.stl" scale="1 1 1"/>
        <mesh name="covering" file="../../meshes/dmanus_sim/meshes/highres/covering.stl" scale="1 1 1"/>
        <mesh name="thumb_cover" file="../../meshes/dmanus_sim/meshes/highres/thumb_cover.stl" scale="1 1 1"/>
        <mesh name="PalmC" file="../../meshes/dmanus_sim/meshes/convex/PalmC.stl" scale="1 1 1"/>
        <mesh name="fingertipc" file="../../meshes/dmanus_sim/meshes/convex/fingertipc.stl" scale="1 1 1"/>
        <mesh name="PalmR" file="../../meshes/dmanus_sim/meshes/convex/PalmR.stl" scale="1 1 1"/>
        <mesh name="PalmL1" file="../../meshes/dmanus_sim/meshes/convex/PalmL1.stl" scale="1 1 1"/>
        <mesh name="PalmL2" file="../../meshes/dmanus_sim/meshes/convex/PalmL2.stl" scale="1 1 1"/>
    </asset>

    <default>
        <default class="dmanus">
            <joint armature="0.001" damping="1" limited="true"/>
            
            <position ctrllimited="true"/>
            <default class="viz_dmanus">
                <geom type="mesh" group="1" rgba="0.25 0.25 0.25 1" contype="0" conaffinity="0"/>
                <site group="1"/>
            </default>

            <default class="viz_skeleton">
                <geom type="mesh" group="1" rgba="1 1 1 1" contype="0" conaffinity="0"/>
                <site group="1"/>
            </default>

            <default class="col_dmanus">
                <geom contype="0" conaffinity="1" condim="4" group="3" margin="0.0005" rgba="0.4 0.5 0.6 1"/>
                <site group="0"/>
            </default>
            
            <default class="vis_site">
                <geom contype="0" conaffinity="0" mass="0" rgba="1 0 0 0" size=".03" type="sphere"/>
            </default>

        </default>
    </default>

    <worldbody>

        <body name="stand" pos="0 -0.7 0.2" euler="-1.57 0 3.14">
            <joint name="ARTx" pos="0 0 0" axis="1 0 0" type="slide" range="-0.25 0.25" damping="20" />
            <joint name="ARTy" pos="0 0 0" axis="0 1 0" type="slide" range="-0.2 0.1" damping="20" />
            <joint name="ARTz" pos="0 0 0" axis="0 0 1" type="slide" range="-0.1 0.7" damping="20" />
            <joint name="ARRx" pos="0 0 0" axis="1 0 0" range="-1.75 1.75" damping="20" />
            <joint name="ARRy" pos="0 0 0" axis="0 1 0" range="-1.75 1.75" damping="20" />
            <joint name="ARRz" pos="0 0 0" axis="0 0 1" range="-2.5 2.5" damping="20" />

            <!--Palm-->
            <body name="palm" pos="0 0 0.09125" childclass="dmanus">
                <body name="wrist_point"> <geom name="wrist_point" class="vis_site" pos="0 0 0"/></body>

                <geom name="skeleton_mesh" mesh="skeleton" pos="-0.001 0 0.1032" class="viz_skeleton"/>
                <geom name="Palmcenter" type="mesh" mesh="PalmC" pos="-0.001 0 0.1032" class="col_dmanus"/>
                <geom name="Palmright" type="mesh" mesh="PalmR" pos="-0.001 0 0.1032" class="col_dmanus"/>
                <geom name="Palmleft1" type="mesh" mesh="PalmL1" pos="-0.001 0 0.1032" class="col_dmanus"/>
                <geom name="Palmleft2" type="mesh" mesh="PalmL2" pos="-0.001 0 0.1032" class="col_dmanus"/>

                <!--Plate-->
                <geom name="plate1_mesh" mesh="plate" pos="0 -0.0255 0.1032" class="viz_dmanus"/>
                <geom name="plate2_mesh" mesh="plate" pos="0 0.0235 0.1032" class="viz_dmanus"/>

                <!--Thumb finger-->
                <body name="Thumb_finger" pos="0.0343 0.0015 0.027" euler="0 1.92 0">
                    <geom name="X4307_mesh" mesh="X430" pos="0 0 0" class="viz_dmanus"/>

                        <body name="thumb_proximal" pos="0 0 0.03475">
                            <body name="thknuckle_point"> <geom name="thknuckle_point" class="vis_site" pos="0 0 0"/></body>

                            <geom name="FR1212" type="box" pos="0 -0.0034 0.0125" size="0.012 0.023875 0.015" class="col_dmanus"/>
                            <geom name="FR1212_mesh" mesh="FR121" pos="0 0 0" class="viz_dmanus"/>
                            <geom name="thumb_cover_mesh" mesh="thumb_cover" pos=" 0 -0.0206 -0.01" euler="0 3.14 3.14"  class="viz_skeleton"/>
                            <geom name="X4308" type="box" pos="0 -0.0045 0.0418" size="0.02325 0.01425 0.017" euler="1.57 1.57 0" class="col_dmanus"/>
                            <geom name="X4308_mesh" mesh="X430" pos="0 0.01875 0.042" euler="1.57 0 1.57" class="viz_dmanus"/>
                            <joint name="TFJ1" type="hinge" pos="0 0 0" axis="0 1 0" limited="true" range="-0.75 0.57"/>

                            <body name="thumb_middle" pos="-0.001 -0.0165 0.042">
                                <geom name="FR1232" type="box" pos="0 0 0.0275" size="0.021 0.0123 0.0275" euler="0.114 0 0" class="col_dmanus"/>
                                <geom name="FR1232_mesh" mesh="FR123" pos="0 0 0" class="viz_dmanus"/>
                                <geom name="cover3_mesh" mesh="covering" pos="0 -0.0148 0.048" euler="0 0 3.14" class="viz_skeleton"/>
                                <geom name="X4309" type="box" pos="0 0 0.078" size="0.01425 0.017 0.02325" euler="0 0 1.57" class="col_dmanus"/>
                                <geom name="X4309_mesh" mesh="X430" pos="0 0 0.055" euler="0 0 1.57" class="viz_dmanus"/>
                                <joint name="TFJ2" type="hinge" pos="0 0 0" axis="1 0 0" limited="true" range="0 1.89"/>

                                <body name="thumb_middle_extra" pos="0 0 0.09025">
                                    <body name="thmiddle_point"> <geom name="thmiddle_point" class="vis_site" pos="0 0 0"/></body>

                                    <geom name="FR1232e" type="box" pos="0 0 0.0275" size="0.021 0.0123 0.0275" euler="0.114 0 0" class="col_dmanus"/>
                                    <geom name="FR1232e_mesh" mesh="FR123" pos="0 0 0" class="viz_dmanus"/>
                                    <geom name="cover3e_mesh" mesh="covering" pos="0 -0.0148 0.048" euler="0 0 3.14" class="viz_skeleton"/>
                                    <geom name="X4309e" type="box" pos="0 0 0.078" size="0.01425 0.017 0.02325" euler="0 0 1.57" class="col_dmanus"/>
                                    <geom name="X4309e_mesh" mesh="X430" pos="0 0 0.055" euler="0 0 1.57" class="viz_dmanus"/>
                                    <joint name="TFJ2e" type="hinge" pos="0 0 0" axis="1 0 0" limited="true" range="0 1.4"/>

                                    <body name="thumb_distal" pos="0 0 0.09025">
                                        <body name="thdistal_point"> <geom name="thdistal_point" class="vis_site" pos="0 0 0.075"/></body> 

                                        <geom name="FR1312" type="box" pos="0 0 0.014" size="0.0205 0.012 0.014" class="col_dmanus"/>
                                        <geom name="FR1312_mesh" mesh="FR121" pos="0 0 0" euler="0 0 1.57" class="viz_dmanus"/>
                                        <geom name="fingertip3_mesh" mesh="fingertip" pos="0 0 0.028" class="viz_dmanus"/>
                                        <geom name="convextip3" type="mesh" mesh="fingertipc" pos="0 0 0.028" class="col_dmanus"/>
                                        <joint name="TFJ3" type="hinge" pos="0 0 0" axis="1 0 0" limited="true" range="0 1.57"/>
                                    </body>
                                </body>
                            </body>
                        </body>
                </body>
                <!--Thumb finger end-->

                <!--Index Finger-->
                <body name="index_finger" pos="0.0445 0.002 0.06325">
                    <geom name="X430_mesh" mesh="X430" pos="0 0 0" class="viz_dmanus"/>

                    <body name="index_proximal" pos="0 0 0.03475">
                        <body name="ffknuckle_point"> <geom name="ffknuckle_point" class="vis_site" pos="0 0 0.03"/></body>

                        <geom name="FR1210" type="box" pos="0 0 0.01308" size="0.012 0.0205 0.015" class="col_dmanus"/>
                        <geom name="FR1210_mesh" mesh="FR121" pos="0 0 0" class="viz_dmanus"/>
                        <geom name="X4302" type="box" pos="0 -0.0045 0.0418" size="0.02325 0.01425 0.017" euler="1.57 1.57 0" class="col_dmanus"/>
                        <geom name="X4302_mesh" mesh="X430" pos="0 0.01875 0.042" euler="1.57 0 1.57" class="viz_dmanus"/>
                        <joint name="IFJ1" type="hinge" pos="0 0 0" axis="0 1 0" limited="true" range="-0.436 0.436"/>

                        <body name="index_middle" pos="-0.001 -0.0165 0.042">
                            <body name="ffmiddle_point"> <geom name="ffmiddle_point" class="vis_site" pos="0 0 0.075"/></body> 

                            <geom name="FR1230" type="box" pos="0 0 0.0275" size="0.021 0.0123 0.0275" euler="0.114 0 0" class="col_dmanus"/>
                            <geom name="FR1230_mesh" mesh="FR123" pos="0 0 0" class="viz_dmanus"/>
                            <geom name="cover1_mesh" mesh="covering" pos="0 -0.0148 0.048"  euler="0 0 3.14" class="viz_skeleton"/>
                            <!-- <geom name="cover1" type="box" pos="0.027 0 0.085" size="0.019 0.014 0.0155" class="col_dmanus"/> -->
                            <geom name="X4303" type="box" pos="0 0 0.078" size="0.01425 0.017 0.02325" euler="0 0 1.57" class="col_dmanus"/>
                            <geom name="X4303_mesh" mesh="X430" pos="0 0 0.055" euler="0 0 1.57" class="viz_dmanus"/>
                            <joint name="IFJ2" type="hinge" pos="0 0 0" axis="1 0 0" limited="true" range="0 1.71"/>

                            <body name="index_distal" pos="0 0 0.09025">
                                <body name="ffdistal_point"> <geom name="ffdistal_point" class="vis_site" pos="0 0 0.075"/></body>

                                <geom name="FR1310" type="box" pos="0 0 0.014" size="0.0205 0.012 0.014" class="col_dmanus"/>
                                <geom name="FR1310_mesh" mesh="FR121" pos="0 0 0" euler="0 0 1.57" class="viz_dmanus"/>
                            <!--  <geom name="fingertip" type="box" pos="0 0 0.071" size="0.01 0.012 0.043" class="col_dmanus"/> -->
                                <geom name="fingertip_mesh" mesh="fingertip" pos="0 0 0.028" class="viz_dmanus"/>
                                <geom name="convextip1" type="mesh" mesh="fingertipc" pos="0 0 0.028" class="col_dmanus"/>
                                <joint name="IFJ3" type="hinge" pos="0 0 0" axis="1 0 0" limited="true" range="0 1.52"/>
                            </body>
                        </body>
                    </body>
                </body>
                <!--Index Finger end-->

                <!--Little Finger-->
                <body name="little_finger" pos="-0.0445 0.002 0.06325">
                        <geom name="X4304_mesh" mesh="X430" pos="0 0 0" class="viz_dmanus"/>

                        <body name="little_proximal" pos="0 0 0.03475">
                            <body name="rfknuckle_point"> <geom name="rfknuckle_point" class="vis_site" pos="0 0 0.03"/></body>

                            <geom name="FR1211" type="box" pos="0 0 0.0125" size="0.012 0.0205 0.015" class="col_dmanus"/>
                            <geom name="FR1211_mesh" mesh="FR121" pos="0 0 0" class="viz_dmanus"/>
                            <geom name="X4305" type="box" pos="0 -0.0045 0.0418" size="0.02325 0.01425 0.017" euler="1.57 1.57 0" class="col_dmanus"/>
                            <geom name="X4305_mesh" mesh="X430" pos="0 0.01875 0.042" euler="1.57 0 1.57" class="viz_dmanus"/>
                            <joint name="LFJ1" type="hinge" pos="0 0 0" axis="0 1 0" limited="true" range="-0.52 0.35"/>

                            <body name="little_middle" pos="-0.001 -0.0165 0.042">
                                <body name="rfmiddle_point"> <geom name="rfmiddle_point" class="vis_site" pos="0 0 0.075"/></body> 

                                <geom name="FR1231" type="box" pos="0 0 0.0275" size="0.021 0.0123 0.0275" euler="0.114 0 0w" class="col_dmanus"/>
                                <geom name="FR1231_mesh" mesh="FR123" pos="0 0 0" class="viz_dmanus"/>
                                <geom name="cover2_mesh" mesh="covering" pos="0 -0.0148 0.048" euler="0 0 3.14" class="viz_skeleton"/>
                                <geom name="X4306" type="box" pos="0 0 0.078" size="0.01425 0.017 0.02325" euler="0 0 1.57" class="col_dmanus"/>
                                <geom name="X4306_mesh" mesh="X430" pos="0 0 0.055" euler="0 0 1.57" class="viz_dmanus"/>
                                <joint name="LFJ2" type="hinge" pos="0 0 0" axis="1 0 0" limited="true" range="0 1.54"/>

                                <body name="little_distal" pos="0 0 0.09025">
                                    <body name="rfdistal_point"> <geom name="rfdistal_point" class="vis_site" pos="0 0 0.075"/></body> 

                                    <geom name="FR1311" type="box" pos="0 0 0.014" size="0.0205 0.012 0.014" class="col_dmanus"/>
                                    <geom name="FR1311_mesh" mesh="FR121" pos="0 0 0" euler="0 0 1.57" class="viz_dmanus"/>
                                <!--  <geom name="fingertip2" type="box" pos="0 0 0.071" size="0.01 0.012 0.043" class="col_dmanus"/> -->
                                    <geom name="fingertip2_mesh" mesh="fingertip" pos="0 0 0.028" class="viz_dmanus"/>
                                    <geom name="convextip2" type="mesh" mesh="fingertipc" pos="0 0 0.028" class="col_dmanus"/>
                                    <joint name="LFJ3" type="hinge" pos="0 0 0" axis="1 0 0" limited="true" range="0 1.48"/>
                                </body>
                            </body>
                        </body>
                </body>
                <!--Little finger end-->

            </body>
        </body>

    </worldbody>

    <contact>
        <pair geom1="FR1232" geom2="FR1210" condim="1" />
        <pair geom1="X4309" geom2="X4302" condim="1" />
        <pair geom1="FR1232e" geom2="FR1230" condim="1" />
        <pair geom1="X4309e" geom2="X4303" condim="1" />
        <pair geom1="FR1312" geom2="FR1310" condim="1" />
        <pair geom1="convextip3" geom2="convextip1" condim="1" />
        <pair geom1="FR1232" geom2="FR1211" condim="1" />
        <pair geom1="X4309" geom2="X4305" condim="1" />
        <pair geom1="FR1232e" geom2="FR1231" condim="1" />
        <pair geom1="X4309e" geom2="X4306" condim="1" />
        <pair geom1="FR1312" geom2="FR1311_mesh" condim="1" />
        <pair geom1="convextip3" geom2="convextip2" condim="1" />
        <pair geom1="convextip3" geom2="FR1212" condim="1" />
        <pair geom1="convextip3" geom2="X4308" condim="1" />
        <pair geom1="FR1210" geom2="FR1211" condim="1" />
        <pair geom1="X4302" geom2="X4305" condim="1" />
        <pair geom1="FR1230" geom2="FR1231" condim="1" />
        <pair geom1="X4303" geom2="X4306" condim="1" />
        <pair geom1="FR1310" geom2="FR1311_mesh" condim="1" />
        <pair geom1="convextip1" geom2="convextip2" condim="1" />
        <pair geom1="Palmcenter" geom2="convextip1" condim="1" />
        <pair geom1="Palmcenter" geom2="convextip2" condim="1" />
        <pair geom1="Palmcenter" geom2="convextip3" condim="1" />
        <pair geom1="Palmright" geom2="convextip1" condim="1" />
        <pair geom1="Palmright" geom2="convextip2" condim="1" />
        <pair geom1="Palmright" geom2="convextip3" condim="1" />
        <pair geom1="Palmleft1" geom2="convextip1" condim="1" />
        <pair geom1="Palmleft1" geom2="convextip2" condim="1" />
        <pair geom1="Palmleft1" geom2="convextip3" condim="1" />
        <pair geom1="Palmleft2" geom2="convextip1" condim="1" />
        <pair geom1="Palmleft2" geom2="convextip2" condim="1" />
        <pair geom1="Palmleft2" geom2="convextip3" condim="1" />
    </contact>
</mujoco>