
<mujoco model="alarmclock">
    <include file='../common.xml'/>
    
    <asset>
        <mesh name="alarmclock" file="../meshes/objects/alarmclock/alarmclock.stl"  />
        <mesh name="contact0" file="../meshes/objects/alarmclock/contact0.stl"  />
    </asset>
    
    <worldbody>
        <body name="object" pos="0.00 0.0 0.035" >
            <joint name="OBJTx" pos="0 0 0" axis="1 0 0" type="slide" class="freejoint" />
            <joint name="OBJTy" pos="0 0 0" axis="0 1 0" type="slide" class="freejoint" />
            <joint name="OBJTz" pos="0 0 0" axis="0 0 1" type="slide" class="freejoint" />
            <joint name="OBJRx" pos="0 0 0" axis="1 0 0" class="freejoint" />
            <joint name="OBJRy" pos="0 0 0" axis="0 1 0" class="freejoint" />
            <joint name="OBJRz" pos="0 0 0" axis="0 0 1" class="freejoint" />
            <geom name="alarmclock_visual" class="object_visual" mesh="alarmclock" rgba="1 0.4 0.43 1" />
            <geom name="alarmclock_contact0" class="object_contact" mesh="contact0"  />
        </body>
    </worldbody>
</mujoco>
