
<mujoco model="banana">
    <include file='../common.xml'/>
    
    <asset>
        <mesh name="banana" file="../meshes/objects/banana/banana.stl"  />
        <mesh name="contact0" file="../meshes/objects/banana/contact0.stl"  />
        <mesh name="contact1" file="../meshes/objects/banana/contact1.stl"  />
        <mesh name="contact2" file="../meshes/objects/banana/contact2.stl"  />
        <mesh name="contact3" file="../meshes/objects/banana/contact3.stl"  />
        <mesh name="contact4" file="../meshes/objects/banana/contact4.stl"  />
    </asset>
    
    <worldbody>
        <body name="object" pos="0.00 0.0 0.035" >
            <joint name="OBJTx" pos="0 0 0" axis="1 0 0" type="slide" class="freejoint" />
            <joint name="OBJTy" pos="0 0 0" axis="0 1 0" type="slide" class="freejoint" />
            <joint name="OBJTz" pos="0 0 0" axis="0 0 1" type="slide" class="freejoint" />
            <joint name="OBJRx" pos="0 0 0" axis="1 0 0" class="freejoint" />
            <joint name="OBJRy" pos="0 0 0" axis="0 1 0" class="freejoint" />
            <joint name="OBJRz" pos="0 0 0" axis="0 0 1" class="freejoint" />
            <geom name="banana_visual" class="object_visual" mesh="banana" rgba="1 1 0 1.0" />
            <geom name="banana_contact0" class="object_contact" mesh="contact0"  />
            <geom name="banana_contact1" class="object_contact" mesh="contact1"  />
            <geom name="banana_contact2" class="object_contact" mesh="contact2"  />
            <geom name="banana_contact3" class="object_contact" mesh="contact3"  />
            <geom name="banana_contact4" class="object_contact" mesh="contact4"  />
        </body>
    </worldbody>
</mujoco>
