
<mujoco model="body">
    <include file='../common.xml'/>
    
    <asset>
        <mesh name="body" file="../meshes/objects/body/body.stl"  />
        <mesh name="contact0" file="../meshes/objects/body/contact0.stl"  />
        <mesh name="contact1" file="../meshes/objects/body/contact1.stl"  />
        <mesh name="contact2" file="../meshes/objects/body/contact2.stl"  />
        <mesh name="contact3" file="../meshes/objects/body/contact3.stl"  />
        <mesh name="contact4" file="../meshes/objects/body/contact4.stl"  />
        <mesh name="contact5" file="../meshes/objects/body/contact5.stl"  />
        <mesh name="contact6" file="../meshes/objects/body/contact6.stl"  />
        <mesh name="contact7" file="../meshes/objects/body/contact7.stl"  />
        <mesh name="contact8" file="../meshes/objects/body/contact8.stl"  />
        <mesh name="contact9" file="../meshes/objects/body/contact9.stl"  />
        <mesh name="contact10" file="../meshes/objects/body/contact10.stl"  />
        <mesh name="contact11" file="../meshes/objects/body/contact11.stl"  />
        <mesh name="contact12" file="../meshes/objects/body/contact12.stl"  />
        <mesh name="contact13" file="../meshes/objects/body/contact13.stl"  />
        <mesh name="contact14" file="../meshes/objects/body/contact14.stl"  />
    </asset>
    
    <worldbody>
        <body name="object" pos="0.00 0.0 0.035" >
            <joint name="OBJTx" pos="0 0 0" axis="1 0 0" type="slide" class="freejoint" />
            <joint name="OBJTy" pos="0 0 0" axis="0 1 0" type="slide" class="freejoint" />
            <joint name="OBJTz" pos="0 0 0" axis="0 0 1" type="slide" class="freejoint" />
            <joint name="OBJRx" pos="0 0 0" axis="1 0 0" class="freejoint" />
            <joint name="OBJRy" pos="0 0 0" axis="0 1 0" class="freejoint" />
            <joint name="OBJRz" pos="0 0 0" axis="0 0 1" class="freejoint" />
            <geom name="body_visual" class="object_visual" mesh="body" rgba="1 0 0 1.0" />
            <geom name="body_contact0" class="object_contact" mesh="contact0"  />
            <geom name="body_contact1" class="object_contact" mesh="contact1"  />
            <geom name="body_contact2" class="object_contact" mesh="contact2"  />
            <geom name="body_contact3" class="object_contact" mesh="contact3"  />
            <geom name="body_contact4" class="object_contact" mesh="contact4"  />
            <geom name="body_contact5" class="object_contact" mesh="contact5"  />
            <geom name="body_contact6" class="object_contact" mesh="contact6"  />
            <geom name="body_contact7" class="object_contact" mesh="contact7"  />
            <geom name="body_contact8" class="object_contact" mesh="contact8"  />
            <geom name="body_contact9" class="object_contact" mesh="contact9"  />
            <geom name="body_contact10" class="object_contact" mesh="contact10"  />
            <geom name="body_contact11" class="object_contact" mesh="contact11"  />
            <geom name="body_contact12" class="object_contact" mesh="contact12"  />
            <geom name="body_contact13" class="object_contact" mesh="contact13"  />
            <geom name="body_contact14" class="object_contact" mesh="contact14"  />
        </body>
    </worldbody>
</mujoco>
