
<mujoco model="bowl">
    <include file='../common.xml'/>
    
    <asset>
        <mesh name="bowl" file="../meshes/objects/bowl/bowl.stl"  />
        <mesh name="contact0" file="../meshes/objects/bowl/contact0.stl"  />
        <mesh name="contact1" file="../meshes/objects/bowl/contact1.stl"  />
        <mesh name="contact2" file="../meshes/objects/bowl/contact2.stl"  />
        <mesh name="contact3" file="../meshes/objects/bowl/contact3.stl"  />
        <mesh name="contact4" file="../meshes/objects/bowl/contact4.stl"  />
        <mesh name="contact5" file="../meshes/objects/bowl/contact5.stl"  />
        <mesh name="contact6" file="../meshes/objects/bowl/contact6.stl"  />
        <mesh name="contact7" file="../meshes/objects/bowl/contact7.stl"  />
        <mesh name="contact8" file="../meshes/objects/bowl/contact8.stl"  />
        <mesh name="contact9" file="../meshes/objects/bowl/contact9.stl"  />
        <mesh name="contact10" file="../meshes/objects/bowl/contact10.stl"  />
        <mesh name="contact11" file="../meshes/objects/bowl/contact11.stl"  />
    </asset>
    
    <worldbody>
        <body name="object" pos="0.00 0.0 0.035" >
            <joint name="OBJTx" pos="0 0 0" axis="1 0 0" type="slide" class="freejoint" />
            <joint name="OBJTy" pos="0 0 0" axis="0 1 0" type="slide" class="freejoint" />
            <joint name="OBJTz" pos="0 0 0" axis="0 0 1" type="slide" class="freejoint" />
            <joint name="OBJRx" pos="0 0 0" axis="1 0 0" class="freejoint" />
            <joint name="OBJRy" pos="0 0 0" axis="0 1 0" class="freejoint" />
            <joint name="OBJRz" pos="0 0 0" axis="0 0 1" class="freejoint" />
            <geom name="bowl_visual" class="object_visual" mesh="bowl" rgba="1 0 0 1.0" />
            <geom name="bowl_contact0" class="object_contact" mesh="contact0"  />
            <geom name="bowl_contact1" class="object_contact" mesh="contact1"  />
            <geom name="bowl_contact2" class="object_contact" mesh="contact2"  />
            <geom name="bowl_contact3" class="object_contact" mesh="contact3"  />
            <geom name="bowl_contact4" class="object_contact" mesh="contact4"  />
            <geom name="bowl_contact5" class="object_contact" mesh="contact5"  />
            <geom name="bowl_contact6" class="object_contact" mesh="contact6"  />
            <geom name="bowl_contact7" class="object_contact" mesh="contact7"  />
            <geom name="bowl_contact8" class="object_contact" mesh="contact8"  />
            <geom name="bowl_contact9" class="object_contact" mesh="contact9"  />
            <geom name="bowl_contact10" class="object_contact" mesh="contact10"  />
            <geom name="bowl_contact11" class="object_contact" mesh="contact11"  />
        </body>
    </worldbody>
</mujoco>
