
<mujoco model="cubesmall">
    <include file='../common.xml'/>
    
    <asset>
        <mesh name="cubesmall" file="../meshes/objects/cubesmall/cubesmall.stl"  />
        <mesh name="contact0" file="../meshes/objects/cubesmall/contact0.stl"  />
    </asset>
    
    <worldbody>
        <body name="object" pos="0.00 0.0 0.035" >
            <joint name="OBJTx" pos="0 0 0" axis="1 0 0" type="slide" class="freejoint" />
            <joint name="OBJTy" pos="0 0 0" axis="0 1 0" type="slide" class="freejoint" />
            <joint name="OBJTz" pos="0 0 0" axis="0 0 1" type="slide" class="freejoint" />
            <joint name="OBJRx" pos="0 0 0" axis="1 0 0" class="freejoint" />
            <joint name="OBJRy" pos="0 0 0" axis="0 1 0" class="freejoint" />
            <joint name="OBJRz" pos="0 0 0" axis="0 0 1" class="freejoint" />
            <geom name="cubesmall_visual" class="object_visual" mesh="cubesmall" rgba="1 0 0 1.0" />
            <geom name="cubesmall_contact0" class="object_contact" mesh="contact0"  />
        </body>
    </worldbody>
</mujoco>
