
<mujoco model="cup">
    <include file='../common.xml'/>
    
    <asset>
        <mesh name="cup" file="../meshes/objects/cup/cup.stl"  />
        <mesh name="contact0" file="../meshes/objects/cup/contact0.stl"  />
        <mesh name="contact1" file="../meshes/objects/cup/contact1.stl"  />
        <mesh name="contact2" file="../meshes/objects/cup/contact2.stl"  />
        <mesh name="contact3" file="../meshes/objects/cup/contact3.stl"  />
        <mesh name="contact4" file="../meshes/objects/cup/contact4.stl"  />
        <mesh name="contact5" file="../meshes/objects/cup/contact5.stl"  />
        <mesh name="contact6" file="../meshes/objects/cup/contact6.stl"  />
        <mesh name="contact7" file="../meshes/objects/cup/contact7.stl"  />
        <mesh name="contact8" file="../meshes/objects/cup/contact8.stl"  />
        <mesh name="contact9" file="../meshes/objects/cup/contact9.stl"  />
        <mesh name="contact10" file="../meshes/objects/cup/contact10.stl"  />
        <mesh name="contact11" file="../meshes/objects/cup/contact11.stl"  />
    </asset>
    
    <worldbody>
        <body name="object" pos="0.00 0.0 0.035" >
            <joint name="OBJTx" pos="0 0 0" axis="1 0 0" type="slide" class="freejoint" />
            <joint name="OBJTy" pos="0 0 0" axis="0 1 0" type="slide" class="freejoint" />
            <joint name="OBJTz" pos="0 0 0" axis="0 0 1" type="slide" class="freejoint" />
            <joint name="OBJRx" pos="0 0 0" axis="1 0 0" class="freejoint" />
            <joint name="OBJRy" pos="0 0 0" axis="0 1 0" class="freejoint" />
            <joint name="OBJRz" pos="0 0 0" axis="0 0 1" class="freejoint" />
            <geom name="cup_visual" class="object_visual" mesh="cup" rgba="1 0.75 0.8 1.0" />
            <geom name="cup_contact0" class="object_contact" mesh="contact0"  />
            <geom name="cup_contact1" class="object_contact" mesh="contact1"  />
            <geom name="cup_contact2" class="object_contact" mesh="contact2"  />
            <geom name="cup_contact3" class="object_contact" mesh="contact3"  />
            <geom name="cup_contact4" class="object_contact" mesh="contact4"  />
            <geom name="cup_contact5" class="object_contact" mesh="contact5"  />
            <geom name="cup_contact6" class="object_contact" mesh="contact6"  />
            <geom name="cup_contact7" class="object_contact" mesh="contact7"  />
            <geom name="cup_contact8" class="object_contact" mesh="contact8"  />
            <geom name="cup_contact9" class="object_contact" mesh="contact9"  />
            <geom name="cup_contact10" class="object_contact" mesh="contact10"  />
            <geom name="cup_contact11" class="object_contact" mesh="contact11"  />
        </body>
    </worldbody>
</mujoco>
