<!-- ======================================================
    Model       :: ADROIT Relocate Object
 
    Mujoco      :: Advanced physics simulation engine
        Source      : www.roboti.us
        Version     : 1.50
        Released    : 17Jan'17
        
    Author      :: Vikash Kumar
        Contacts    : vikash@cs.washington.edu
        Last edits  : 17Jan'17
    Designed for :: Demo Augmented Policy Gradient (DAPG)
    Copyright   :: Vikash Kumar
        Licensed under Apache License, Version 2.0 (the "License"); you may not use this file except in compliance with the License. You may obtain a copy of the License at http://www.apache.org/licenses/LICENSE-2.0 Unless required by applicable law or agreed to in writing, software distributed under the License is distributed on an "AS IS" BASIS, WITHOUT WARRANTIES OR CONDITIONS OF ANY KIND, either express or implied. See the License for the specific language governing permissions and limitations under the License.
====================================================== -->


<mujoco model="dapghammer">
    <include file='../common.xml'/>
    
    <asset>
        <texture type="cube" name="wood" file="../textures/wood.png" />
        <material name="MatWood" texture="wood" texrepeat="3 3" specular="0.4" shininess="0.1" />
    </asset>
    
    <worldbody>
        <body name="object" pos="0 -0.2 0.035" quat="0.707388 0.706825 0 0">
            <inertial pos="-0.11025 0 0" quat="0.50001 0.49999 0.49999 0.50001" mass="0.253442" diaginertia="0.00349644 0.00345287 8.947e-05" />
            <joint name="OBJTx" pos="0 0 0" axis="1 0 0" type="slide" limited="false" damping="0" />
            <joint name="OBJTy" pos="0 0 0" axis="0 1 0" type="slide" limited="false" damping="0" />
            <joint name="OBJTz" pos="0 0 0" axis="0 0 1" type="slide" limited="false" damping="0" />
            <joint name="OBJRx" pos="0 0 0" axis="1 0 0" limited="false" damping="0.1" />
            <joint name="OBJRy" pos="0 0 0" axis="0 1 0" limited="false" damping="0.1" />
            <joint name="OBJRz" pos="0 0 0" axis="0 0 1" limited="false" damping="0.1" />
            <geom name="handle" size="0.025 0.05" quat="0.707388 0 0.706825 0" type="capsule" condim="4" material="MatWood" />
            <geom name="neck" size="0.007 0.085" pos="-0.14 0 0" quat="0.707388 0 0.706825 0" type="capsule" condim="4" rgba="1 1 1 1" />
            <geom name="head" size="0.02 0.04" pos="-0.24 0 0" type="cylinder" condim="4" rgba="0.4 0.4 0.4 1" />
            <site name="tool" pos="-0.2 0 -0.04" size="0.01" group="4" rgba="0.4 0.8 0.4 1" />
            <body name="mid_point" pos="-0.12 0 0"> <geom name="mid_point" contype="0" conaffinity="0" rgba="1 0 0 0" size=".03" type="sphere"/></body>
        </body>
    </worldbody>
</mujoco>
