<!-- ======================================================
    Model       :: ADROIT Relocate Object
 
    Mujoco      :: Advanced physics simulation engine
        Source      : www.roboti.us
        Version     : 1.50
        Released    : 17Jan'17
        
    Author      :: Vikash Kumar
        Contacts    : vikash@cs.washington.edu
        Last edits  : 17Jan'17
    Designed for :: Demo Augmented Policy Gradient (DAPG)
    Copyright   :: Vikash Kumar
        Licensed under Apache License, Version 2.0 (the "License"); you may not use this file except in compliance with the License. You may obtain a copy of the License at http://www.apache.org/licenses/LICENSE-2.0 Unless required by applicable law or agreed to in writing, software distributed under the License is distributed on an "AS IS" BASIS, WITHOUT WARRANTIES OR CONDITIONS OF ANY KIND, either express or implied. See the License for the specific language governing permissions and limitations under the License.
====================================================== -->


<mujoco model="door">
    <include file='../common.xml'/>
    
    <asset>
        <texture type="cube" name="wood" file="../textures/wood.png" />
        <texture type="cube" name="foil" file="../textures/silverRaw.png" />
        <material name="MatWood" texture="wood" texrepeat="3 3" specular="0.4" shininess="0.1" />
        <material name="MatFoil" texture="foil" specular="1" shininess="0.3" rgba="0.9 0.9 0.9 1" />
    </asset>
    
    <worldbody>
        <body name="frame" pos="-0.107339 0.0435293 0.447376">
            <inertial pos="0.29 0 0" quat="0.5 0.5 0.5 0.5" mass="7.85398" diaginertia="0.923301 0.764585 0.168533" />
            <geom size="0.05 0.25" pos="0.6 0 0" type="cylinder" material="MatWood" rgba="1 0 0 1" />
            <geom size="0.05 0.25" pos="-0.02 0 0" type="cylinder" material="MatWood" rgba="1 0 0 1" />
            <site name="S_handle_target" pos="0.75 -0.5 -.18" size="0.025" group='3'/>
            <body name="door" pos="0.29 0 0">
                <inertial pos="0.0296816 -0.00152345 0" quat="0.701072 0 0 0.713091" mass="2.43455" diaginertia="0.0913751 0.0521615 0.043714" />
                <joint name="door_hinge" pos="0.31 0 0" axis="0 0 1" range="0 1.57" damping="1" frictionloss="2" />
                <geom size="0.2 0.05 0.25" type="box" friction="1 1 1" material="MatWood" />
                <geom size="0.05 0.25" pos="0.2 0 0" type="cylinder" material="MatWood" />
                <geom size="0.05 0.25" pos="-0.2 0 0" type="cylinder" material="MatWood" />
                <body name="latch" pos="-0.15 0 -0.025">
                    <inertial pos="-0.017762 0.0138544 0" quat="0.365653 0.605347 -0.36522 0.605365" mass="3.53743" diaginertia="0.0483771 0.0410001 0.0111013" />
                    <joint name="latch" pos="0 0 0" axis="0 1 0" range="0 1.8" frictionloss="5" />
                    <geom size="0.05 0.15" quat="0.707388 0.706825 0 0" type="cylinder" material="MatFoil" />
                    <geom size="0.02 0.1" pos="0.1 -0.15 0" quat="0.707388 0 0.706825 0" type="capsule" material="MatFoil" />
                    <geom size="0.04 0.07" pos="-0.1 0.1 0" quat="0.707388 0 0.706825 0" type="capsule" material="MatFoil" />
                    <site name="S_handle" pos="0.15 -0.15 0" size="0.025" group="3"/>
                    <body name="object" pos="0.15 -0.15 0"> <geom name="object" contype="0" conaffinity="0" mass="0" rgba="1 0 0 0" size=".025" type="sphere"/></body>
                </body>
            </body>
        </body>
    </worldbody>
</mujoco>
