
<mujoco model="flashlight">
    <include file='../common.xml'/>
    
    <asset>
        <mesh name="flashlight" file="../meshes/objects/flashlight/flashlight.stl"  />
        <mesh name="contact0" file="../meshes/objects/flashlight/contact0.stl"  />
        <mesh name="contact1" file="../meshes/objects/flashlight/contact1.stl"  />
    </asset>
    
    <worldbody>
        <body name="object" pos="0.00 0.0 0.035" >
            <joint name="OBJTx" pos="0 0 0" axis="1 0 0" type="slide" class="freejoint" />
            <joint name="OBJTy" pos="0 0 0" axis="0 1 0" type="slide" class="freejoint" />
            <joint name="OBJTz" pos="0 0 0" axis="0 0 1" type="slide" class="freejoint" />
            <joint name="OBJRx" pos="0 0 0" axis="1 0 0" class="freejoint" />
            <joint name="OBJRy" pos="0 0 0" axis="0 1 0" class="freejoint" />
            <joint name="OBJRz" pos="0 0 0" axis="0 0 1" class="freejoint" />
            <geom name="flashlight_visual" class="object_visual" mesh="flashlight" rgba="1 0.65 0 1.0" />
            <geom name="flashlight_contact0" class="object_contact" mesh="contact0"  />
            <geom name="flashlight_contact1" class="object_contact" mesh="contact1"  />
        </body>
    </worldbody>
</mujoco>
