
<mujoco model="flute">
    <include file='../common.xml'/>
    
    <asset>
        <mesh name="flute" file="../meshes/objects/flute/flute.stl"  />
        <mesh name="contact0" file="../meshes/objects/flute/contact0.stl"  />
    </asset>
    
    <worldbody>
        <body name="object" pos="0.00 0.0 0.035" >
            <joint name="OBJTx" pos="0 0 0" axis="1 0 0" type="slide" class="freejoint" />
            <joint name="OBJTy" pos="0 0 0" axis="0 1 0" type="slide" class="freejoint" />
            <joint name="OBJTz" pos="0 0 0" axis="0 0 1" type="slide" class="freejoint" />
            <joint name="OBJRx" pos="0 0 0" axis="1 0 0" class="freejoint" />
            <joint name="OBJRy" pos="0 0 0" axis="0 1 0" class="freejoint" />
            <joint name="OBJRz" pos="0 0 0" axis="0 0 1" class="freejoint" />
            <geom name="flute_visual" class="object_visual" mesh="flute" rgba="0.73 0.5 0.39 1.0" />
            <geom name="flute_contact0" class="object_contact" mesh="contact0"  />
        </body>
    </worldbody>
</mujoco>
