
<mujoco model="knife">
    <include file='../common.xml'/>
    
    <asset>
        <mesh name="knife" file="../meshes/objects/knife/knife.stl"  />
        <mesh name="contact0" file="../meshes/objects/knife/contact0.stl"  />
        <mesh name="contact1" file="../meshes/objects/knife/contact1.stl"  />
    </asset>
    
    <worldbody>
        <body name="object" pos="0.00 0.0 0.035" >
            <joint name="OBJTx" pos="0 0 0" axis="1 0 0" type="slide" class="freejoint" />
            <joint name="OBJTy" pos="0 0 0" axis="0 1 0" type="slide" class="freejoint" />
            <joint name="OBJTz" pos="0 0 0" axis="0 0 1" type="slide" class="freejoint" />
            <joint name="OBJRx" pos="0 0 0" axis="1 0 0" class="freejoint" />
            <joint name="OBJRy" pos="0 0 0" axis="0 1 0" class="freejoint" />
            <joint name="OBJRz" pos="0 0 0" axis="0 0 1" class="freejoint" />
            <geom name="knife_visual" class="object_visual" mesh="knife" rgba="1 0 0 0.0" />
            <geom name="knife_contact0" class="object_contact" mesh="contact0" rgba="0.75 0.75 0.75 1" />
            <geom name="knife_contact1" class="object_contact" mesh="contact1" rgba="0.1 0.1 0.1 1" />
        </body>
    </worldbody>
</mujoco>
