
<mujoco model="mug">
    <include file='../common.xml'/>
    
    <asset>
        <mesh name="mug" file="../meshes/objects/mug/mug.stl"  />
        <mesh name="contact0" file="../meshes/objects/mug/contact0.stl"  />
        <mesh name="contact1" file="../meshes/objects/mug/contact1.stl"  />
        <mesh name="contact2" file="../meshes/objects/mug/contact2.stl"  />
        <mesh name="contact3" file="../meshes/objects/mug/contact3.stl"  />
        <mesh name="contact4" file="../meshes/objects/mug/contact4.stl"  />
        <mesh name="contact5" file="../meshes/objects/mug/contact5.stl"  />
        <mesh name="contact6" file="../meshes/objects/mug/contact6.stl"  />
        <mesh name="contact7" file="../meshes/objects/mug/contact7.stl"  />
        <mesh name="contact8" file="../meshes/objects/mug/contact8.stl"  />
        <mesh name="contact9" file="../meshes/objects/mug/contact9.stl"  />
        <mesh name="contact10" file="../meshes/objects/mug/contact10.stl"  />
        <mesh name="contact11" file="../meshes/objects/mug/contact11.stl"  />
        <mesh name="contact12" file="../meshes/objects/mug/contact12.stl"  />
        <mesh name="contact13" file="../meshes/objects/mug/contact13.stl"  />
    </asset>
    
    <worldbody>
        <body name="object" pos="0.00 0.0 0.035" >
            <joint name="OBJTx" pos="0 0 0" axis="1 0 0" type="slide" class="freejoint" />
            <joint name="OBJTy" pos="0 0 0" axis="0 1 0" type="slide" class="freejoint" />
            <joint name="OBJTz" pos="0 0 0" axis="0 0 1" type="slide" class="freejoint" />
            <joint name="OBJRx" pos="0 0 0" axis="1 0 0" class="freejoint" />
            <joint name="OBJRy" pos="0 0 0" axis="0 1 0" class="freejoint" />
            <joint name="OBJRz" pos="0 0 0" axis="0 0 1" class="freejoint" />
            <geom name="mug_visual" class="object_visual" mesh="mug" rgba="0 0 0.7 1.0" />
            <geom name="mug_contact0" class="object_contact" mesh="contact0"  />
            <geom name="mug_contact1" class="object_contact" mesh="contact1"  />
            <geom name="mug_contact2" class="object_contact" mesh="contact2"  />
            <geom name="mug_contact3" class="object_contact" mesh="contact3"  />
            <geom name="mug_contact4" class="object_contact" mesh="contact4"  />
            <geom name="mug_contact5" class="object_contact" mesh="contact5"  />
            <geom name="mug_contact6" class="object_contact" mesh="contact6"  />
            <geom name="mug_contact7" class="object_contact" mesh="contact7"  />
            <geom name="mug_contact8" class="object_contact" mesh="contact8"  />
            <geom name="mug_contact9" class="object_contact" mesh="contact9"  />
            <geom name="mug_contact10" class="object_contact" mesh="contact10"  />
            <geom name="mug_contact11" class="object_contact" mesh="contact11"  />
            <geom name="mug_contact12" class="object_contact" mesh="contact12"  />
            <geom name="mug_contact13" class="object_contact" mesh="contact13"  />
        </body>
    </worldbody>
</mujoco>
