
<mujoco model="stamp">
    <include file='../common.xml'/>
    
    <asset>
        <mesh name="stamp" file="../meshes/objects/stamp/stamp.stl"  />
        <mesh name="contact0" file="../meshes/objects/stamp/contact0.stl"  />
        <mesh name="contact1" file="../meshes/objects/stamp/contact1.stl"  />
        <mesh name="contact2" file="../meshes/objects/stamp/contact2.stl"  />
    </asset>
    
    <worldbody>
        <body name="object" pos="0.00 0.0 0.035" >
            <joint name="OBJTx" pos="0 0 0" axis="1 0 0" type="slide" class="freejoint" />
            <joint name="OBJTy" pos="0 0 0" axis="0 1 0" type="slide" class="freejoint" />
            <joint name="OBJTz" pos="0 0 0" axis="0 0 1" type="slide" class="freejoint" />
            <joint name="OBJRx" pos="0 0 0" axis="1 0 0" class="freejoint" />
            <joint name="OBJRy" pos="0 0 0" axis="0 1 0" class="freejoint" />
            <joint name="OBJRz" pos="0 0 0" axis="0 0 1" class="freejoint" />
            <geom name="stamp_visual" class="object_visual" mesh="stamp" rgba="1 0 0 0.0" />
            <geom name="stamp_contact0" class="object_contact" mesh="contact0" rgba="0 0 0 1" />
            <geom name="stamp_contact1" class="object_contact" mesh="contact1" rgba="1 1 1 1" />
            <geom name="stamp_contact2" class="object_contact" mesh="contact2" rgba="0.73 0.5 0.39 1" />
        </body>
    </worldbody>
</mujoco>
