
<mujoco model="stapler">
    <include file='../common.xml'/>
    
    <asset>
        <mesh name="stapler" file="../meshes/objects/stapler/stapler.stl"  />
        <mesh name="contact0" file="../meshes/objects/stapler/contact0.stl"  />
        <mesh name="contact1" file="../meshes/objects/stapler/contact1.stl"  />
        <mesh name="contact2" file="../meshes/objects/stapler/contact2.stl"  />
        <mesh name="contact3" file="../meshes/objects/stapler/contact3.stl"  />
        <mesh name="contact4" file="../meshes/objects/stapler/contact4.stl"  />
    </asset>
    
    <worldbody>
        <body name="object" pos="0.00 0.0 0.035" >
            <joint name="OBJTx" pos="0 0 0" axis="1 0 0" type="slide" class="freejoint" />
            <joint name="OBJTy" pos="0 0 0" axis="0 1 0" type="slide" class="freejoint" />
            <joint name="OBJTz" pos="0 0 0" axis="0 0 1" type="slide" class="freejoint" />
            <joint name="OBJRx" pos="0 0 0" axis="1 0 0" class="freejoint" />
            <joint name="OBJRy" pos="0 0 0" axis="0 1 0" class="freejoint" />
            <joint name="OBJRz" pos="0 0 0" axis="0 0 1" class="freejoint" />
            <geom name="stapler_visual" class="object_visual" mesh="stapler" rgba="1 0 0 0.0" />
            <geom name="stapler_contact0" class="object_contact" mesh="contact0"  />
            <geom name="stapler_contact1" class="object_contact" mesh="contact1" rgba="0 1 1 0" />
            <geom name="stapler_contact2" class="object_contact" mesh="contact2" rgba="0.8 0.8 0.8 1" />
            <geom name="stapler_contact3" class="object_contact" mesh="contact3" rgba="0.2 0.2 0.2 1" />
            <geom name="stapler_contact4" class="object_contact" mesh="contact4" rgba="0.2 0.2 0.2 1" />
        </body>
    </worldbody>
</mujoco>
