
<mujoco model="teapot">
    <include file='../common.xml'/>
    
    <asset>
        <mesh name="teapot" file="../meshes/objects/teapot/teapot.stl"  />
        <mesh name="contact0" file="../meshes/objects/teapot/contact0.stl"  />
        <mesh name="contact1" file="../meshes/objects/teapot/contact1.stl"  />
        <mesh name="contact2" file="../meshes/objects/teapot/contact2.stl"  />
        <mesh name="contact3" file="../meshes/objects/teapot/contact3.stl"  />
        <mesh name="contact4" file="../meshes/objects/teapot/contact4.stl"  />
        <mesh name="contact5" file="../meshes/objects/teapot/contact5.stl"  />
        <mesh name="contact6" file="../meshes/objects/teapot/contact6.stl"  />
        <mesh name="contact7" file="../meshes/objects/teapot/contact7.stl"  />
        <mesh name="contact8" file="../meshes/objects/teapot/contact8.stl"  />
        <mesh name="contact9" file="../meshes/objects/teapot/contact9.stl"  />
        <mesh name="contact10" file="../meshes/objects/teapot/contact10.stl"  />
        <mesh name="contact11" file="../meshes/objects/teapot/contact11.stl"  />
        <mesh name="contact12" file="../meshes/objects/teapot/contact12.stl"  />
        <mesh name="contact13" file="../meshes/objects/teapot/contact13.stl"  />
        <mesh name="contact14" file="../meshes/objects/teapot/contact14.stl"  />
        <mesh name="contact15" file="../meshes/objects/teapot/contact15.stl"  />
        <mesh name="contact16" file="../meshes/objects/teapot/contact16.stl"  />
        <mesh name="contact17" file="../meshes/objects/teapot/contact17.stl"  />
        <mesh name="contact18" file="../meshes/objects/teapot/contact18.stl"  />
        <mesh name="contact19" file="../meshes/objects/teapot/contact19.stl"  />
        <mesh name="contact20" file="../meshes/objects/teapot/contact20.stl"  />
        <mesh name="contact21" file="../meshes/objects/teapot/contact21.stl"  />
        <mesh name="contact22" file="../meshes/objects/teapot/contact22.stl"  />
        <mesh name="contact23" file="../meshes/objects/teapot/contact23.stl"  />
        <mesh name="contact24" file="../meshes/objects/teapot/contact24.stl"  />
        <mesh name="contact25" file="../meshes/objects/teapot/contact25.stl"  />
        <mesh name="contact26" file="../meshes/objects/teapot/contact26.stl"  />
        <mesh name="contact27" file="../meshes/objects/teapot/contact27.stl"  />
        <mesh name="contact28" file="../meshes/objects/teapot/contact28.stl"  />
        <mesh name="contact29" file="../meshes/objects/teapot/contact29.stl"  />
        <mesh name="contact30" file="../meshes/objects/teapot/contact30.stl"  />
        <mesh name="contact31" file="../meshes/objects/teapot/contact31.stl"  />
        <mesh name="contact32" file="../meshes/objects/teapot/contact32.stl"  />
        <mesh name="contact33" file="../meshes/objects/teapot/contact33.stl"  />
        <mesh name="contact34" file="../meshes/objects/teapot/contact34.stl"  />
        <mesh name="contact35" file="../meshes/objects/teapot/contact35.stl"  />
        <mesh name="contact36" file="../meshes/objects/teapot/contact36.stl"  />
        <mesh name="contact37" file="../meshes/objects/teapot/contact37.stl"  />
        <mesh name="contact38" file="../meshes/objects/teapot/contact38.stl"  />
        <mesh name="contact39" file="../meshes/objects/teapot/contact39.stl"  />
        <mesh name="contact40" file="../meshes/objects/teapot/contact40.stl"  />
    </asset>
    
    <worldbody>
        <body name="object" pos="0.00 0.0 0.035" >
            <joint name="OBJTx" pos="0 0 0" axis="1 0 0" type="slide" class="freejoint" />
            <joint name="OBJTy" pos="0 0 0" axis="0 1 0" type="slide" class="freejoint" />
            <joint name="OBJTz" pos="0 0 0" axis="0 0 1" type="slide" class="freejoint" />
            <joint name="OBJRx" pos="0 0 0" axis="1 0 0" class="freejoint" />
            <joint name="OBJRy" pos="0 0 0" axis="0 1 0" class="freejoint" />
            <joint name="OBJRz" pos="0 0 0" axis="0 0 1" class="freejoint" />
            <geom name="teapot_visual" class="object_visual" mesh="teapot" rgba="1 0 0 1.0" />
            <geom name="teapot_contact0" class="object_contact" mesh="contact0"  />
            <geom name="teapot_contact1" class="object_contact" mesh="contact1"  />
            <geom name="teapot_contact2" class="object_contact" mesh="contact2"  />
            <geom name="teapot_contact3" class="object_contact" mesh="contact3"  />
            <geom name="teapot_contact4" class="object_contact" mesh="contact4"  />
            <geom name="teapot_contact5" class="object_contact" mesh="contact5"  />
            <geom name="teapot_contact6" class="object_contact" mesh="contact6"  />
            <geom name="teapot_contact7" class="object_contact" mesh="contact7"  />
            <geom name="teapot_contact8" class="object_contact" mesh="contact8"  />
            <geom name="teapot_contact9" class="object_contact" mesh="contact9"  />
            <geom name="teapot_contact10" class="object_contact" mesh="contact10"  />
            <geom name="teapot_contact11" class="object_contact" mesh="contact11"  />
            <geom name="teapot_contact12" class="object_contact" mesh="contact12"  />
            <geom name="teapot_contact13" class="object_contact" mesh="contact13"  />
            <geom name="teapot_contact14" class="object_contact" mesh="contact14"  />
            <geom name="teapot_contact15" class="object_contact" mesh="contact15"  />
            <geom name="teapot_contact16" class="object_contact" mesh="contact16"  />
            <geom name="teapot_contact17" class="object_contact" mesh="contact17"  />
            <geom name="teapot_contact18" class="object_contact" mesh="contact18"  />
            <geom name="teapot_contact19" class="object_contact" mesh="contact19"  />
            <geom name="teapot_contact20" class="object_contact" mesh="contact20"  />
            <geom name="teapot_contact21" class="object_contact" mesh="contact21"  />
            <geom name="teapot_contact22" class="object_contact" mesh="contact22"  />
            <geom name="teapot_contact23" class="object_contact" mesh="contact23"  />
            <geom name="teapot_contact24" class="object_contact" mesh="contact24"  />
            <geom name="teapot_contact25" class="object_contact" mesh="contact25"  />
            <geom name="teapot_contact26" class="object_contact" mesh="contact26"  />
            <geom name="teapot_contact27" class="object_contact" mesh="contact27"  />
            <geom name="teapot_contact28" class="object_contact" mesh="contact28"  />
            <geom name="teapot_contact29" class="object_contact" mesh="contact29"  />
            <geom name="teapot_contact30" class="object_contact" mesh="contact30"  />
            <geom name="teapot_contact31" class="object_contact" mesh="contact31"  />
            <geom name="teapot_contact32" class="object_contact" mesh="contact32"  />
            <geom name="teapot_contact33" class="object_contact" mesh="contact33"  />
            <geom name="teapot_contact34" class="object_contact" mesh="contact34"  />
            <geom name="teapot_contact35" class="object_contact" mesh="contact35"  />
            <geom name="teapot_contact36" class="object_contact" mesh="contact36"  />
            <geom name="teapot_contact37" class="object_contact" mesh="contact37"  />
            <geom name="teapot_contact38" class="object_contact" mesh="contact38"  />
            <geom name="teapot_contact39" class="object_contact" mesh="contact39"  />
            <geom name="teapot_contact40" class="object_contact" mesh="contact40"  />
        </body>
    </worldbody>
</mujoco>
