
<mujoco model="toruslarge">
    <include file='../common.xml'/>
    
    <asset>
        <mesh name="toruslarge" file="../meshes/objects/toruslarge/toruslarge.stl"  />
        <mesh name="contact0" file="../meshes/objects/toruslarge/contact0.stl"  />
        <mesh name="contact1" file="../meshes/objects/toruslarge/contact1.stl"  />
        <mesh name="contact2" file="../meshes/objects/toruslarge/contact2.stl"  />
        <mesh name="contact3" file="../meshes/objects/toruslarge/contact3.stl"  />
        <mesh name="contact4" file="../meshes/objects/toruslarge/contact4.stl"  />
    </asset>
    
    <worldbody>
        <body name="object" pos="0.00 0.0 0.035" >
            <joint name="OBJTx" pos="0 0 0" axis="1 0 0" type="slide" class="freejoint" />
            <joint name="OBJTy" pos="0 0 0" axis="0 1 0" type="slide" class="freejoint" />
            <joint name="OBJTz" pos="0 0 0" axis="0 0 1" type="slide" class="freejoint" />
            <joint name="OBJRx" pos="0 0 0" axis="1 0 0" class="freejoint" />
            <joint name="OBJRy" pos="0 0 0" axis="0 1 0" class="freejoint" />
            <joint name="OBJRz" pos="0 0 0" axis="0 0 1" class="freejoint" />
            <geom name="toruslarge_visual" class="object_visual" mesh="toruslarge" rgba="0 0.6 0 1.0" />
            <geom name="toruslarge_contact0" class="object_contact" mesh="contact0"  />
            <geom name="toruslarge_contact1" class="object_contact" mesh="contact1"  />
            <geom name="toruslarge_contact2" class="object_contact" mesh="contact2"  />
            <geom name="toruslarge_contact3" class="object_contact" mesh="contact3"  />
            <geom name="toruslarge_contact4" class="object_contact" mesh="contact4"  />
        </body>
    </worldbody>
</mujoco>
