
<mujoco model="watch">
    <include file='../common.xml'/>
    
    <asset>
        <mesh name="watch" file="../meshes/objects/watch/watch.stl"  />
        <mesh name="contact0" file="../meshes/objects/watch/contact0.stl"  />
        <mesh name="contact1" file="../meshes/objects/watch/contact1.stl"  />
        <mesh name="contact2" file="../meshes/objects/watch/contact2.stl"  />
        <mesh name="contact3" file="../meshes/objects/watch/contact3.stl"  />
        <mesh name="contact4" file="../meshes/objects/watch/contact4.stl"  />
        <mesh name="contact5" file="../meshes/objects/watch/contact5.stl"  />
        <mesh name="contact6" file="../meshes/objects/watch/contact6.stl"  />
        <mesh name="contact7" file="../meshes/objects/watch/contact7.stl"  />
        <mesh name="contact8" file="../meshes/objects/watch/contact8.stl"  />
    </asset>
    
    <worldbody>
        <body name="object" pos="0.00 0.0 0.035" >
            <joint name="OBJTx" pos="0 0 0" axis="1 0 0" type="slide" class="freejoint" />
            <joint name="OBJTy" pos="0 0 0" axis="0 1 0" type="slide" class="freejoint" />
            <joint name="OBJTz" pos="0 0 0" axis="0 0 1" type="slide" class="freejoint" />
            <joint name="OBJRx" pos="0 0 0" axis="1 0 0" class="freejoint" />
            <joint name="OBJRy" pos="0 0 0" axis="0 1 0" class="freejoint" />
            <joint name="OBJRz" pos="0 0 0" axis="0 0 1" class="freejoint" />
            <geom name="watch_visual" class="object_visual" mesh="watch" rgba="0 0.5 0 1.0" />
            <geom name="watch_contact0" class="object_contact" mesh="contact0"  />
            <geom name="watch_contact1" class="object_contact" mesh="contact1"  />
            <geom name="watch_contact2" class="object_contact" mesh="contact2"  />
            <geom name="watch_contact3" class="object_contact" mesh="contact3"  />
            <geom name="watch_contact4" class="object_contact" mesh="contact4"  />
            <geom name="watch_contact5" class="object_contact" mesh="contact5"  />
            <geom name="watch_contact6" class="object_contact" mesh="contact6"  />
            <geom name="watch_contact7" class="object_contact" mesh="contact7"  />
            <geom name="watch_contact8" class="object_contact" mesh="contact8"  />
        </body>
    </worldbody>
</mujoco>
