
<mujoco model="wineglass">
    <include file='../common.xml'/>
    
    <asset>
        <mesh name="wineglass" file="../meshes/objects/wineglass/wineglass.stl"  />
        <mesh name="contact0" file="../meshes/objects/wineglass/contact0.stl"  />
        <mesh name="contact1" file="../meshes/objects/wineglass/contact1.stl"  />
        <mesh name="contact2" file="../meshes/objects/wineglass/contact2.stl"  />
        <mesh name="contact3" file="../meshes/objects/wineglass/contact3.stl"  />
        <mesh name="contact4" file="../meshes/objects/wineglass/contact4.stl"  />
        <mesh name="contact5" file="../meshes/objects/wineglass/contact5.stl"  />
        <mesh name="contact6" file="../meshes/objects/wineglass/contact6.stl"  />
        <mesh name="contact7" file="../meshes/objects/wineglass/contact7.stl"  />
        <mesh name="contact8" file="../meshes/objects/wineglass/contact8.stl"  />
        <mesh name="contact9" file="../meshes/objects/wineglass/contact9.stl"  />
        <mesh name="contact10" file="../meshes/objects/wineglass/contact10.stl"  />
        <mesh name="contact11" file="../meshes/objects/wineglass/contact11.stl"  />
        <mesh name="contact12" file="../meshes/objects/wineglass/contact12.stl"  />
        <mesh name="contact13" file="../meshes/objects/wineglass/contact13.stl"  />
        <mesh name="contact14" file="../meshes/objects/wineglass/contact14.stl"  />
        <mesh name="contact15" file="../meshes/objects/wineglass/contact15.stl"  />
        <mesh name="contact16" file="../meshes/objects/wineglass/contact16.stl"  />
        <mesh name="contact17" file="../meshes/objects/wineglass/contact17.stl"  />
        <mesh name="contact18" file="../meshes/objects/wineglass/contact18.stl"  />
        <mesh name="contact19" file="../meshes/objects/wineglass/contact19.stl"  />
        <mesh name="contact20" file="../meshes/objects/wineglass/contact20.stl"  />
        <mesh name="contact21" file="../meshes/objects/wineglass/contact21.stl"  />
        <mesh name="contact22" file="../meshes/objects/wineglass/contact22.stl"  />
        <mesh name="contact23" file="../meshes/objects/wineglass/contact23.stl"  />
        <mesh name="contact24" file="../meshes/objects/wineglass/contact24.stl"  />
        <mesh name="contact25" file="../meshes/objects/wineglass/contact25.stl"  />
        <mesh name="contact26" file="../meshes/objects/wineglass/contact26.stl"  />
        <mesh name="contact27" file="../meshes/objects/wineglass/contact27.stl"  />
        <mesh name="contact28" file="../meshes/objects/wineglass/contact28.stl"  />
        <mesh name="contact29" file="../meshes/objects/wineglass/contact29.stl"  />
        <mesh name="contact30" file="../meshes/objects/wineglass/contact30.stl"  />
        <mesh name="contact31" file="../meshes/objects/wineglass/contact31.stl"  />
        <mesh name="contact32" file="../meshes/objects/wineglass/contact32.stl"  />
        <mesh name="contact33" file="../meshes/objects/wineglass/contact33.stl"  />
    </asset>
    
    <worldbody>
        <body name="object" pos="0.00 0.0 0.035" >
            <joint name="OBJTx" pos="0 0 0" axis="1 0 0" type="slide" class="freejoint" />
            <joint name="OBJTy" pos="0 0 0" axis="0 1 0" type="slide" class="freejoint" />
            <joint name="OBJTz" pos="0 0 0" axis="0 0 1" type="slide" class="freejoint" />
            <joint name="OBJRx" pos="0 0 0" axis="1 0 0" class="freejoint" />
            <joint name="OBJRy" pos="0 0 0" axis="0 1 0" class="freejoint" />
            <joint name="OBJRz" pos="0 0 0" axis="0 0 1" class="freejoint" />
            <geom name="wineglass_visual" class="object_visual" mesh="wineglass" rgba="0.75 0.75 0.75 0.9" />
            <geom name="wineglass_contact0" class="object_contact" mesh="contact0"  />
            <geom name="wineglass_contact1" class="object_contact" mesh="contact1"  />
            <geom name="wineglass_contact2" class="object_contact" mesh="contact2"  />
            <geom name="wineglass_contact3" class="object_contact" mesh="contact3"  />
            <geom name="wineglass_contact4" class="object_contact" mesh="contact4"  />
            <geom name="wineglass_contact5" class="object_contact" mesh="contact5"  />
            <geom name="wineglass_contact6" class="object_contact" mesh="contact6"  />
            <geom name="wineglass_contact7" class="object_contact" mesh="contact7"  />
            <geom name="wineglass_contact8" class="object_contact" mesh="contact8"  />
            <geom name="wineglass_contact9" class="object_contact" mesh="contact9"  />
            <geom name="wineglass_contact10" class="object_contact" mesh="contact10"  />
            <geom name="wineglass_contact11" class="object_contact" mesh="contact11"  />
            <geom name="wineglass_contact12" class="object_contact" mesh="contact12"  />
            <geom name="wineglass_contact13" class="object_contact" mesh="contact13"  />
            <geom name="wineglass_contact14" class="object_contact" mesh="contact14"  />
            <geom name="wineglass_contact15" class="object_contact" mesh="contact15"  />
            <geom name="wineglass_contact16" class="object_contact" mesh="contact16"  />
            <geom name="wineglass_contact17" class="object_contact" mesh="contact17"  />
            <geom name="wineglass_contact18" class="object_contact" mesh="contact18"  />
            <geom name="wineglass_contact19" class="object_contact" mesh="contact19"  />
            <geom name="wineglass_contact20" class="object_contact" mesh="contact20"  />
            <geom name="wineglass_contact21" class="object_contact" mesh="contact21"  />
            <geom name="wineglass_contact22" class="object_contact" mesh="contact22"  />
            <geom name="wineglass_contact23" class="object_contact" mesh="contact23"  />
            <geom name="wineglass_contact24" class="object_contact" mesh="contact24"  />
            <geom name="wineglass_contact25" class="object_contact" mesh="contact25"  />
            <geom name="wineglass_contact26" class="object_contact" mesh="contact26"  />
            <geom name="wineglass_contact27" class="object_contact" mesh="contact27"  />
            <geom name="wineglass_contact28" class="object_contact" mesh="contact28"  />
            <geom name="wineglass_contact29" class="object_contact" mesh="contact29"  />
            <geom name="wineglass_contact30" class="object_contact" mesh="contact30"  />
            <geom name="wineglass_contact31" class="object_contact" mesh="contact31"  />
            <geom name="wineglass_contact32" class="object_contact" mesh="contact32"  />
            <geom name="wineglass_contact33" class="object_contact" mesh="contact33"  />
        </body>
    </worldbody>
</mujoco>
